Workbook

Sheet Notes
A1: QuinStreet LBO - purpose and method
A2: Tests whether Ridgeline Capital (fictional $2B fund) could buy QuinStreet (QNST) and earn its target return, and solves for the maximum price it could pay.
A3: QuinStreet was the top-ranked eligible company in the screen (docs/scoring_methodology.md).
A5: Key modeling choices
A6: 1. EBITDA is strict (operating income + D&A). Stock-based compensation is treated as a real cost, assumed replaced by cash pay after the buyout.
A7: 2. Lenders may add back stock-based compensation when sizing debt (switch on Inputs). This raises debt and risk.
A8: 3. Capex includes capitalized internal software development ($10.9M in FY2026), which the screen's CapEx metric excluded.
A9: 4. Interest is charged on beginning-of-year debt to avoid a circular reference.
A10: 5. No dividends during the hold, so IRR = MOIC^(1/years) - 1.
A11: 6. Exit at today's market EV/EBITDA, with no control premium at exit.
A13: Limitations
A14: Annual model; simplified tax (no use of tax losses); one senior loan; illustrative interest rate; base-case operating assumptions are judgments, not forecasts.
A15: Share price is a single day's close (2026-10-23). Not investment advice.

Sheet Inputs
A1: QuinStreet (QNST) LBO - Inputs
A2: $ millions unless stated. Blue = hard-coded input; black = formula; yellow fill = key assumption to flex.
A4: Item | B4: Value | C4: Unit | D4: Source / rationale
A5: Market data
A6: Current share price | B6: 16.52 | C6: $ / share | D6: Nasdaq.com historical quotes, close 2026-10-23 (data/raw/share_prices.csv)
A7: Shares outstanding | B7: 57.1 | C7: millions | D7: 10-K FY2026 cover page, shares as of 2026-08-21 (SEC dei data)
A8: Offer premium to current price | B8: 0.3 | C8: % | D8: Assumption: typical take-private premium of 20-40%
A10: FY2026 actuals (fiscal year ended June 30, 2026)
A11: Revenue | B11: 1293.7 | C11: $M | D11: QNST 10-K FY2026, income statement
A12: EBITDA (strict: operating income + D&A) | B12: 60.6 | C12: $M | D12: Calculated in src/metrics.py; SBC treated as a real cost
A13: Depreciation and amortization | B13: 25.2 | C13: $M | D13: QNST 10-K FY2026, cash flow statement
A14: Stock-based compensation | B14: 37.4 | C14: $M | D14: QNST 10-K FY2026, cash flow statement
A15: Capital expenditures | B15: 3.4 | C15: $M | D15: QNST 10-K FY2026, cash flow statement
A16: Capitalized internal software development | B16: 10.9 | C16: $M | D16: QNST 10-K FY2026, cash flow statement (treated as capex in this model)
A17: Cash and cash equivalents | B17: 128.3 | C17: $M | D17: QNST 10-K FY2026, balance sheet
A18: Existing debt (revolver borrowings) | B18: 70 | C18: $M | D18: QNST 10-K FY2026; repaid at closing
A20: Transaction and financing assumptions
A21: Minimum operating cash kept in the business | B21: 30 | C21: $M | D21: Assumption
A22: Transaction and financing fees | B22: 0.03 | C22: % of purchase equity | D22: Assumption
A23: Lenders add back SBC? (1 = yes, 0 = no) | B23: 1 | C23: switch | D23: Assumption: market practice is to lend on adjusted EBITDA
A24: Senior term loan | B24: 4.5 | C24: x lending EBITDA | D24: Assumption: typical for a mid-sized services business
A25: Interest rate on senior debt | B25: 0.085 | C25: % per year | D25: Assumption (illustrative base rate + spread)
A26: Mandatory amortization | B26: 0.01 | C26: % of original loan / year | D26: Assumption: typical term loan
A27: Cash sweep | B27: 1 | C27: % of excess cash used to repay debt | D27: Assumption
A28: Tax rate | B28: 0.25 | C28: % | D28: Same assumption as the screen (mandate, section 7)
A29: Ridgeline maximum equity per deal | B29: 330 | C29: $M | D29: Mandate, section 1 ($2B fund, 6-10 deals)
A30: Target IRR | B30: 0.2 | C30: % per year | D30: Assumption: common PE return hurdle
A32: Operating assumptions (FY2027-FY2031, base case)
A33: Revenue growth per year | B33: 0.08 | C33: % | D33: Assumption: organic growth well below the 30.6% CAGR, which was partly acquired
A34: EBITDA margin reached in FY2031 (strict) | B34: 0.06 | C34: % | D34: Assumption: modest improvement from 4.7% (value-creation case)
A35: D&A | B35: =B13/B11 -> 0.019479014 | C35: % of revenue | D35: Held at FY2026 level
A36: Capex incl. capitalized software | B36: =(B15+B16)/B11 -> 0.011053567 | C36: % of revenue | D36: Held at FY2026 level
A37: Change in working capital | B37: 0.05 | C37: % of revenue increase | D37: Assumption
A38: Exit multiple | B38: 14.6 | C38: x EBITDA (strict) | D38: Assumption: today's market multiple (Model row 18), no control premium at exit

Sheet Model
A1: QuinStreet (QNST) LBO - Model
A2: $ millions unless stated. Green = link to Inputs; black = formula. Every value traces to the Inputs sheet.
A4: A. Purchase price
A5: Current share price ($) | B5: =Inputs!$B$6 -> 16.52
A6: Offer premium | B6: =Inputs!$B$8 -> 0.3
A7: Offer price per share ($) | B7: =B5*(1+B6) -> 21.476
A8: Shares outstanding (millions) | B8: =Inputs!$B$7 -> 57.1
A9: Offer equity value | B9: =B7*B8 -> 1226.2796
A10: Plus: existing debt | B10: =Inputs!$B$18 -> 70
A11: Less: cash | B11: =Inputs!$B$17 -> 128.3
A12: Entry enterprise value | B12: =B9+B10-B11 -> 1167.9796
A13: FY2026 EBITDA (strict) | B13: =Inputs!$B$12 -> 60.6
A14: Entry EV / EBITDA (strict) | B14: =B12/B13 -> 19.273591
A15: Lending EBITDA (strict + SBC if lenders add it back) | B15: =Inputs!$B$12+Inputs!$B$23*Inputs!$B$14 -> 98
A16: Entry EV / lending EBITDA | B16: =B12/B15 -> 11.918159
A17: Memo: current market enterprise value (no premium) | B17: =B5*B8+B10-B11 -> 884.992
A18: Memo: current market EV / EBITDA (strict) | B18: =B17/B13 -> 14.603828
A20: B. Sources and uses at closing
A21: Uses
A22: Purchase of equity | B22: =B9 -> 1226.2796
A23: Refinance existing debt | B23: =B10 -> 70
A24: Transaction and financing fees | B24: =B9*Inputs!$B$22 -> 36.788388
A25: Total uses | B25: =SUM(B22:B24) -> 1333.068
A26: Sources
A27: Excess cash on the balance sheet | B27: =MAX(0,B11-Inputs!$B$21) -> 98.3
A28: Senior term loan | B28: =B15*Inputs!$B$24 -> 441
A29: Ridgeline equity | B29: =B25-B27-B28 -> 793.76799
A30: Total sources | B30: =SUM(B27:B29) -> 1333.068
A31: Check: sources - uses (must be 0) | B31: =B30-B25 -> 0
A32: Ridgeline maximum equity per deal | B32: =Inputs!$B$29 -> 330
A33: Equity within Ridgeline's limit? | B33: =IF(B29<=B32,"YES","NO") -> NO
A34: Senior debt / FY2026 EBITDA (strict) | B34: =B28/B13 -> 7.2772277
A36: C. Operating projections (fiscal years end June 30)
A37: Fiscal year | C37: FY2026A | D37: FY2027E | E37: FY2028E | F37: FY2029E | G37: FY2030E | H37: FY2031E
A38: Years since closing | C38: 0 | D38: =C38+1 -> 1 | E38: =D38+1 -> 2 | F38: =E38+1 -> 3 | G38: =F38+1 -> 4 | H38: =G38+1 -> 5
A39: Revenue | C39: =Inputs!$B$11 -> 1293.7 | D39: =C39*(1+Inputs!$B$33) -> 1397.196 | E39: =D39*(1+Inputs!$B$33) -> 1508.9717 | F39: =E39*(1+Inputs!$B$33) -> 1629.6894 | G39: =F39*(1+Inputs!$B$33) -> 1760.0646 | H39: =G39*(1+Inputs!$B$33) -> 1900.8697
A40: Revenue growth | D40: =D39/C39-1 -> 0.08 | E40: =E39/D39-1 -> 0.08 | F40: =F39/E39-1 -> 0.08 | G40: =G39/F39-1 -> 0.08 | H40: =H39/G39-1 -> 0.08
A41: EBITDA margin | C41: =C42/C39 -> 0.04684239 | D41: =$C$41+(Inputs!$B$34-$C$41)*D38/$H$38 -> 0.049473912 | E41: =$C$41+(Inputs!$B$34-$C$41)*E38/$H$38 -> 0.052105434 | F41: =$C$41+(Inputs!$B$34-$C$41)*F38/$H$38 -> 0.054736956 | G41: =$C$41+(Inputs!$B$34-$C$41)*G38/$H$38 -> 0.057368478 | H41: =$C$41+(Inputs!$B$34-$C$41)*H38/$H$38 -> 0.06
A42: EBITDA (strict) | C42: =Inputs!$B$12 -> 60.6 | D42: =D39*D41 -> 69.124752 | E42: =E39*E41 -> 78.625624 | F42: =F39*F41 -> 89.204238 | G42: =G39*G41 -> 100.97223 | H42: =H39*H41 -> 114.05218
A43: Depreciation and amortization | C43: =Inputs!$B$13 -> 25.2 | D43: =D39*Inputs!$B$35 -> 27.216 | E43: =E39*Inputs!$B$35 -> 29.39328 | F43: =F39*Inputs!$B$35 -> 31.744742 | G43: =G39*Inputs!$B$35 -> 34.284322 | H43: =H39*Inputs!$B$35 -> 37.027068
...
